version: "3.8"

services:
  db:
    image: postgres:15
    volumes:
      - postgres_data:/var/lib/postgresql/data/
    environment:
      POSTGRES_DB: django_db
      POSTGRES_USER: django_user
      POSTGRES_PASSWORD: django_password
    ports:
      - "5432:5432"
    healthcheck:
      test: ["CMD-SHELL", "pg_isready -U django_user -d django_db"]
      interval: 30s
      timeout: 10s
      retries: 3

  web:
    build:
      context: .
      dockerfile: Dockerfile.dev
    command: uv run python manage.py runserver 0.0.0.0:8000
    volumes:
      - .:/app
      - ./logs:/app/logs
    ports:
      - "8000:8000"
    environment:
      - DEBUG=1
      - DJANGO_SETTINGS_MODULE=config.settings.development
      - DATABASE_URL=postgresql://django_user:django_password@db:5432/django_db
      - DB_HOST=db
      - DB_NAME=django_db
      - DB_USER=django_user
      - DB_PASSWORD=django_password
      - DB_PORT=5432
      - PYTHONUNBUFFERED=1
      - PYTHONDONTWRITEBYTECODE=1
    depends_on:
      db:
        condition: service_healthy
    stdin_open: true
    tty: true

  redis:
    image: redis:7-alpine
    ports:
      - "6379:6379"

volumes:
  postgres_data:
